Traceback (most recent call last):
  File "/Users/rodrigo/.venvs/compiler/lib/python3.6/site-packages/wfc/core.py", line 137, in compile
    out_file.write(context.build_script())
  File "/Users/rodrigo/.venvs/compiler/lib/python3.6/site-packages/wfc/core.py", line 76, in build_script
    return self._output.get_script()
  File "/Users/rodrigo/.venvs/compiler/lib/python3.6/site-packages/wfc/output/__init__.py", line 37, in get_script
    return self._output_module.get_script()
  File "/Users/rodrigo/.venvs/compiler/lib/python3.6/site-packages/wfc/output/v20.py", line 67, in get_script
    _script.perform_sanity_checks()
  File "/Users/rodrigo/.venvs/compiler/lib/python3.6/site-packages/wfc/output/__init__.py", line 142, in perform_sanity_checks
    context
  File "/Users/rodrigo/.venvs/compiler/lib/python3.6/site-packages/wfc/output/__init__.py", line 56, in _raise_missing_component_error
    raise UndefinedFlow(context, name)
wfc.errors.UndefinedFlow: <exception str() failed>

During handling of the above exception, another exception occurred:

Traceback (most recent call last):
  File "/Users/rodrigo/.venvs/compiler/bin/wfc", line 11, in <module>
    load_entry_point('wfc==1.1.0', 'console_scripts', 'wfc')()
  File "/Users/rodrigo/.venvs/compiler/lib/python3.6/site-packages/wfc/cli.py", line 22, in main
    rc = core.compile(context)
  File "/Users/rodrigo/.venvs/compiler/lib/python3.6/site-packages/wfc/core.py", line 140, in compile
    sys.stderr.write(f'{error}\n')
  File "/Users/rodrigo/.venvs/compiler/lib/python3.6/site-packages/wfc/errors.py", line 64, in __str__
    message = self._build_error_message()
  File "/Users/rodrigo/.venvs/compiler/lib/python3.6/site-packages/wfc/errors.py", line 125, in _build_error_message
    return f'Flow "{self.args[0]}" is not defined'
IndexError: tuple index out of range
